Workbook
Name Equipos: #REF!
Name España: #REF!
Name Jugadores: #REF!

Sheet ORTIZ
AF2: Participación: 20 €
K4: MACROPORRA MUNDIAL 2026
K8: Nombre: | N8: ORTIZ
K11: e-mail: | N11: alejandro@orconsa.es
B14: Guarda el archivo con tu nombre y envíalo a iperezurrutia@gmail.com o por WHATSAPP Fecha límite de envío y de pago: Primer partido Mundial (11/06/2026 21:00)
B16: ESCRIBE UN SIGNO (10 PUNTOS) Y UN RESULTADO (25 PUNTOS)
AF17: DIECISEISAVOS
B18: Grupo A | E18: Resultado | G18: 1X2 | H18: Ptos | I18: Ptos | L18: Grupo B | O18: Resultado | Q18: 1X2 | R18: Ptos | S18: Ptos | V18: Grupo C | Y18: Resultado | AA18: 1X2 | AB18: Ptos | AC18: Ptos | AF18: 20ptos/equipo ó 40ptos/equipo+casilla | AJ18: Ptos
B19: 46184 | C19: 0.875 | D19: Mexico | E19: 2-1 | F19: Sudafrica | G19: 1 | L19: 46185 | M19: 0.875 | N19: Canada | O19: 1-0 | P19: Bosnia | Q19: 1 | V19: 46187 | W19: 0 | X19: Brasil | Y19: 2-2 | Z19: Marruecos | AA19: X | AE19: 73 | AF19: 46201 | AG19: 0.875 | AH19: SUDAFRICA | AI19: CANADA
B20: 46185 | C20: 0.16666667 | D20: Corea del Sur | E20: 0-1 | F20: Chequia | G20: 2 | L20: 46186 | M20: 0.875 | N20: Catar | O20: 0-2 | P20: Suiza | Q20: 2 | V20: 46187 | W20: 0.125 | X20: Haiti | Y20: 0-1 | Z20: Escocia | AA20: 2 | AE20: 74 | AF20: 46202 | AG20: 0.9375 | AH20: ALEMANIA | AI20: SUECIA
B21: 46191 | C21: 0.75 | D21: Chequia | E21: 1-1 | F21: Sudafrica | G21: X | L21: 46191 | M21: 0.875 | N21: Suiza | O21: 2-0 | P21: Bosnia | Q21: 1 | V21: 46193 | W21: 0 | X21: Escocia | Y21: 1-1 | Z21: Marruecos | AA21: X | AE21: 75 | AF21: 46203 | AG21: 0.125 | AH21: JAPON | AI21: MARRUECOS
B22: 46192 | C22: 0.125 | D22: Mexico | E22: 2-0 | F22: Corea del Sur | G22: 1 | L22: 46192 | M22: 0 | N22: Canada | O22: 2-0 | P22: Catar | Q22: 1 | V22: 46193 | W22: 0.10416667 | X22: Brasil | Y22: 3-0 | Z22: Haiti | AA22: 1 | AE22: 76 | AF22: 46202 | AG22: 0.79166667 | AH22: BRASIL | AI22: PAISES BAJOS
B23: 46198 | C23: 0.125 | D23: Chequia | E23: 1-1 | F23: Mexico | G23: X | L23: 46197 | M23: 0.875 | N23: Bosnia | O23: 1-0 | P23: Catar | Q23: X | V23: 46198 | W23: 0 | X23: Escocia | Y23: 3-0 | Z23: Brasil | AA23: 2 | AE23: 77 | AF23: 46203 | AG23: 0.95833333 | AH23: FRANCIA | AI23: NUEVA ZELANDA
B24: 46198 | C24: 0.125 | D24: Sudafrica | E24: 2-1 | F24: Corea del Sur | G24: 1 | L24: 46197 | M24: 0.875 | N24: Suiza | O24: 1-1 | P24: Canada | Q24: X | V24: 46198 | W24: 0 | X24: Marruecos | Y24: 2-0 | Z24: Haiti | AA24: 1 | AE24: 78 | AF24: 46203 | AG24: 0.79166667 | AH24: ECUADOR | AI24: NORUEGA
AE25: 79 | AF25: 46204 | AG25: 0.041666667 | AH25: MEXICO | AI25: COSTA DE MARFIL
AE26: 80 | AF26: 46204 | AG26: 0.75 | AH26: CROACIA | AI26: SENEGAL
B27: Grupo D | E27: Resultado | G27: 1X2 | H27: Ptos | I27: Ptos | L27: Grupo E | O27: Resultado | Q27: 1X2 | R27: Ptos | S27: Ptos | V27: Grupo F | Y27: Resultado | AA27: 1X2 | AB27: Ptos | AC27: Ptos | AE27: 81 | AF27: 46205 | AG27: 0.083333333 | AH27: TURQUIA | AI27: ARGELIA
B28: 46186 | C28: 0.125 | D28: EEUU | E28: 2-0 | F28: Paraguay | G28: 1 | L28: 46187 | M28: 0.79166667 | N28: Alemania | O28: 3-0 | P28: Curazao | Q28: 1 | V28: 46187 | W28: 0.91666667 | X28: Paises Bajos | Y28: 1-1 | Z28: Japon | AA28: X | AE28: 82 | AF28: 46204 | AG28: 0.91666667 | AH28: BELGICA | AI28: CHEQUIA
B29: 46187 | C29: 0.25 | D29: Australia | E29: 0-2 | F29: Turquia | G29: 2 | L29: 46188 | M29: 0.041666667 | N29: Costa de Marfil | O29: 0-2 | P29: Ecuador | Q29: 1 | V29: 46188 | W29: 0.16666667 | X29: Suecia | Y29: 1-1 | Z29: Tunez | AA29: 1 | AE29: 83 | AF29: 46206 | AG29: 0.041666667 | AH29: COLOMBIA | AI29: INGLATERRA
B30: 46192 | C30: 0.875 | D30: EEUU | E30: 1-0 | F30: Australia | G30: 1 | L30: 46193 | M30: 0.91666667 | N30: Alemania | O30: 1-0 | P30: Costa de Marfil | Q30: 1 | V30: 46193 | W30: 0.79166667 | X30: Paises Bajos | Y30: 2-1 | Z30: Suecia | AA30: X | AE30: 84 | AF30: 46205 | AG30: 0.875 | AH30: ESPAÑA | AI30: AUSTRIA
B31: 46193 | C31: 0.20833333 | D31: Turquia | E31: 2-0 | F31: Paraguay | G31: 1 | L31: 46194 | M31: 0.083333333 | N31: Ecuador | O31: 1-0 | P31: Curazao | Q31: 1 | V31: 46194 | W31: 0.25 | X31: Tunez | Y31: 0-2 | Z31: Japon | AA31: 2 | AE31: 85 | AF31: 46206 | AG31: 0.20833333 | AH31: SUIZA | AI31: JAPON
B32: 46199 | C32: 0.16666667 | D32: Turquia | E32: 1-1 | F32: EEUU | G32: X | L32: 46198 | M32: 0.91666667 | N32: Curazao | O32: 1-1 | P32: Costa de Marfil | Q32: X | V32: 46199 | W32: 0.041666667 | X32: Japon | Y32: 2-0 | Z32: Suecia | AA32: X | AE32: 86 | AF32: 46207 | AG32: 0 | AH32: ARGENTINA | AI32: URUGUAY
B33: 46199 | C33: 0.16666667 | D33: Paraguay | E33: 1-1 | F33: Australia | G33: 1 | L33: 46198 | M33: 0.91666667 | N33: Ecuador | O33: 0-1 | P33: Alemania | Q33: 2 | V33: 46199 | W33: 0.041666667 | X33: Tunez | Y33: 0-2 | Z33: Paises Bajos | AA33: 2 | AE33: 87 | AF33: 46207 | AG33: 0.14583333 | AH33: PORTUGAL | AI33: PARAGUAY
AE34: 88 | AF34: 46206 | AG34: 0.83333333 | AH34: EEUU | AI34: EGIPTO
B36: Grupo G | E36: Resultado | G36: 1X2 | H36: Ptos | I36: Ptos | L36: Grupo H | O36: Resultado | Q36: 1X2 | R36: Ptos | S36: Ptos | V36: Grupo I | Y36: Resultado | AA36: 1X2 | AB36: Ptos | AC36: Ptos | AF36: OCTAVOS
B37: 46188 | C37: 0.875 | D37: Belgica | E37: 2-1 | F37: Egipto | G37: 1 | L37: 46188 | M37: 0.75 | N37: España | O37: 3-0 | P37: Cabo Verde | Q37: 1 | V37: 46189 | W37: 0.875 | X37: Francia | Y37: 3-0 | Z37: Senegal | AA37: 1 | AF37: 35ptos/equipo ó 55ptos/equipo+casilla | AJ37: Ptos
B38: 46189 | C38: 0.125 | D38: Iran | E38: 1-1 | F38: Nueva Zelanda | G38: 2 | L38: 46189 | M38: 0 | N38: Arabia Saudi | O38: 0-2 | P38: Uruguay | Q38: 2 | V38: 46190 | W38: 0 | X38: Irak | Y38: 0-2 | Z38: Noruega | AA38: 2 | AE38: 89 | AF38: 46207 | AG38: 0.95833333 | AH38: ALEMANIA | AI38: FRANCIA
B39: 46194 | C39: 0.875 | D39: Belgica | E39: 3-0 | F39: Iran | G39: 1 | L39: 46194 | M39: 0.75 | N39: España | O39: 2-0 | P39: Arabia Saudi | Q39: 1 | V39: 46195 | W39: 0.95833333 | X39: Francia | Y39: 2-0 | Z39: Irak | AA39: 1 | AE39: 90 | AF39: 46207 | AG39: 0.79166667 | AH39: CANADA | AI39: MARRUECOS
B40: 46195 | C40: 0.125 | D40: Nueva Zelanda | E40: 0-1 | F40: Egipto | G40: 2 | L40: 46195 | M40: 0 | N40: Uruguay | O40: 1-0 | P40: Cabo Verde | Q40: 1 | V40: 46196 | W40: 0.083333333 | X40: Noruega | Y40: 2-0 | Z40: Senegal | AA40: 1 | AE40: 91 | AF40: 46208 | AG40: 0.91666667 | AH40: BRASIL | AI40: NORUEGA
B41: 46200 | C41: 0.20833333 | D41: Egipto | E41: 2-0 | F41: Iran | G41: 1 | L41: 46200 | M41: 0.083333333 | N41: Cabo Verde | O41: 2-0 | P41: Arabia Saudi | Q41: X | V41: 46199 | W41: 0.875 | X41: Noruega | Y41: 1-1 | Z41: Francia | AA41: 2 | AE41: 92 | AF41: 46209 | AG41: 0.083333333 | AH41: MEXICO | AI41: CROACIA
B42: 46200 | C42: 0.20833333 | D42: Nueva Zelanda | E42: 0-3 | F42: Belgica | G42: 2 | L42: 46200 | M42: 0.083333333 | N42: Uruguay | O42: 1-3 | P42: España | Q42: X | V42: 46199 | W42: 0.875 | X42: Senegal | Y42: 2-0 | Z42: Irak | AA42: X | AE42: 93 | AF42: 46209 | AG42: 0.875 | AH42: INGLATERRA | AI42: ESPAÑA
AE43: 94 | AF43: 46210 | AG43: 0.083333333 | AH43: TURQUIA | AI43: BELGICA
AE44: 95 | AF44: 46210 | AG44: 0.75 | AH44: ARGENTINA | AI44: EEUU
B45: Grupo J | E45: Resultado | G45: 1X2 | H45: Ptos | I45: Ptos | L45: Grupo K | O45: Resultado | Q45: 1X2 | R45: Ptos | S45: Ptos | V45: Grupo L | Y45: Resultado | AA45: 1X2 | AB45: Ptos | AC45: Ptos | AE45: 96 | AF45: 46210 | AG45: 0.91666667 | AH45: JAPON | AI45: PORTUGAL
B46: 46190 | C46: 0.125 | D46: Argentina | E46: 3-0 | F46: Argelia | G46: 1 | L46: 46190 | M46: 0.79166667 | N46: Portugal | O46: 3-0 | P46: Congo | Q46: 1 | V46: 46190 | W46: 0.91666667 | X46: Inglaterra | Y46: 1-1 | Z46: Croacia | AA46: 1
B47: 46190 | C47: 0.25 | D47: Austria | E47: 2-0 | F47: Jordania | G47: 1 | L47: 46191 | M47: 0.16666667 | N47: Uzbekistan | O47: 0-1 | P47: Colombia | Q47: 2 | V47: 46191 | W47: 0.041666667 | X47: Ghana | Y47: 0-1 | Z47: Panama | AA47: 2 | AF47: CUARTOS
B48: 46195 | C48: 0.79166667 | D48: Argentina | E48: 1-0 | F48: Austria | G48: 1 | L48: 46196 | M48: 0.79166667 | N48: Portugal | O48: 2-0 | P48: Uzbekistan | Q48: 1 | V48: 46196 | W48: 0.91666667 | X48: Inglaterra | Y48: 1-0 | Z48: Ghana | AA48: 1 | AF48: 50ptos/equipo ó 75ptos/equipo+casilla | AJ48: Ptos
B49: 46196 | C49: 0.20833333 | D49: Jordania | E49: 0-1 | F49: Argelia | G49: 2 | L49: 46197 | M49: 0.16666667 | N49: Colombia | O49: 2-0 | P49: Congo | Q49: 1 | V49: 46197 | W49: 0.041666667 | X49: Panama | Y49: 1-2 | Z49: Croacia | AA49: 2 | AE49: 97 | AF49: 46212 | AG49: 0.91666667 | AH49: FRANCIA | AI49: MARRUECOS
B50: 46201 | C50: 0.16666667 | D50: Argelia | E50: 1-1 | F50: Austria | G50: 2 | L50: 46201 | M50: 0.0625 | N50: Colombia | O50: 0-3 | P50: Portugal | Q50: 2 | V50: 46200 | W50: 0.95833333 | X50: Panama | Y50: 1-2 | Z50: Inglaterra | AA50: 2 | AE50: 98 | AF50: 46213 | AG50: 0.875 | AH50: ESPAÑA | AI50: TURQUIA
B51: 46201 | C51: 0.16666667 | D51: Jordania | E51: 1-2 | F51: Argentina | G51: 2 | L51: 46201 | M51: 0.0625 | N51: Congo | O51: 2-0 | P51: Uzbekistan | Q51: 1 | V51: 46200 | W51: 0.95833333 | X51: Croacia | Y51: 1-0 | Z51: Ghana | AA51: 1 | AE51: 99 | AF51: 46214 | AG51: 0.95833333 | AH51: BRASIL | AI51: MEXICO
...

Sheet ORTIZ 2
B2: Selección Española | C2: 15puntos | D2: Ptos
B3: Caerá España en penaltis | C3: NO
B4: Se lesionará alguien (lesión, no molestias…) | C4: SI
B5: Anularan a España algun gol por el VAR | C5: SI
B6: Se perderá alguien algún partido por sanción | C6: NO
B7: Marcara Victor Muñoz (no vale penalti) | C7: SI
B8: Luis de la Fuente verá tarjeta? | C8: NO
B9: Jugara algún minuto Yeremy Pino | C9: SI
B10: Jugará otro portero que no sea Unai Simon | C10: SI
C11: 30puntos
B12: Primer tarjeteado | C12: Marcos Llorente
B13: Quien marcará más goles (Victor Muñoz, Borja Iglesias, Yeremy Pino) | C13: Victor Muñoz
B14: Quien marcará más goles (Oyarzabal, Dani Olmo, Yamal) | C14: Oyarzabal
B15: Quien dará más asistencias (Pedri, Yamal, Zubimendi) | C15: Pedri
B16: Quien recibirá más tarjetas amarillas (Cucurella, Pedro Porro, Le Normand) | C16: Cucurella
B17: Primer cambio (primero en salir del campo) | C17: Dani Olmo
B18: Primer cambio (primero en entrar al campo) | C18: Ferran
B19: Cuántos partidos jugará España | C19: 8
C20: 60puntos
B21: Máximo goleador | C21: Oyarzabal
B22: Maximo asistente | C22: Pedri
B23: Cuántos goles marcará España | C23: 15
B24: Cuántos goles le marcarán a España | C24: 6
D25: =SUM(D3:D24) -> 0
B27: Generales | C27: 15puntos | D27: Ptos
B28: Marcara Cristiano de falta | C28: SI
B29: Cuántos 0-0 habrá en la fase de grupos | C29: 4
B30: Primera selección en marcar un gol (no cuenta en propia) | C30: Mexico | F30: ALINEACION | G30: =ORTIZ!H72 -> 0
B31: Primera selección en recibir una tarjeta | C31: Sudafrica | F31: PRONÓSTICOS: | G31: =ORTIZ!AB53+ORTIZ!AC53 -> 0
B32: Mayor número de goles que habrá en un partido. Solo 90 min | C32: 8 | F32: GOLES: | G32: =SUM(ORTIZ!R60:R64)*40 -> 0
B33: Mayor goleada (diferencia de goles entre los 2 equipos). Solo 90 min | C33: 4 | F33: PORTEROS | G33: =SUM(ORTIZ!AA61:AA63)*30+SUM(ORTIZ!AB61:AB63)*40 -> 0
C34: 30puntos | F34: PREGUNTAS: | G34: =G59 -> 0
B35: Número de goles del máximo goleador | C35: 7 | F35: PUNTUACIÓN FINAL | G35: =SUM(G28:G34) -> 0
B36: Selección más goleadora | C36: Francia
B37: Selección menos goleada | C37: Alemania
B38: Selección más goleada | C38: Curazao
B39: Selección menos goleadora | C39: Cabo Verde
B40: Primera selección en parar un penalti | C40: Brasil
B41: Primera selección con un jugador expulsado | C41: Bosnia
B42: Acabará alguna selección con 0 puntos | C42: SI
...

Sheet MIGUEL
AF2: Participación: 20 €
K4: MACROPORRA MUNDIAL 2026
K8: Nombre: | P8: Miguel Angel
K11: e-mail: | R11: miguelnoa21@gmail.com
B14: Guarda el archivo con tu nombre y envíalo a iperezurrutia@gmail.com o por WHATSAPP Fecha límite de envío y de pago: Primer partido Mundial (11/06/2026 21:00)
B16: ESCRIBE UN SIGNO (10 PUNTOS) Y UN RESULTADO (25 PUNTOS)
AF17: DIECISEISAVOS
B18: Grupo A | E18: Resultado | G18: 1X2 | H18: Ptos | I18: Ptos | L18: Grupo B | O18: Resultado | Q18: 1X2 | R18: Ptos | S18: Ptos | V18: Grupo C | Y18: Resultado | AA18: 1X2 | AB18: Ptos | AC18: Ptos | AF18: 20ptos/equipo ó 40ptos/equipo+casilla | AJ18: Ptos
B19: 46184 | C19: 0.875 | D19: Mexico | E19: 2-1 | F19: Sudafrica | G19: X | L19: 46185 | M19: 0.875 | N19: Canada | O19: 1-2 | P19: Bosnia | Q19: X | V19: 46187 | W19: 0 | X19: Brasil | Y19: 2-2 | Z19: Marruecos | AA19: 2 | AE19: 73 | AF19: 46201 | AG19: 0.875 | AH19: sudafrica | AI19: bosnia
B20: 46185 | C20: 0.16666667 | D20: Corea del Sur | E20: 1-2 | F20: Chequia | G20: x | L20: 46186 | M20: 0.875 | N20: Catar | O20: 0-1 | P20: Suiza | Q20: X | V20: 46187 | W20: 0.125 | X20: Haiti | Y20: 1-2 | Z20: Escocia | AA20: X | AE20: 74 | AF20: 46202 | AG20: 0.9375 | AH20: alemania | AI20: tunez
B21: 46191 | C21: 0.75 | D21: Chequia | E21: 3-2 | F21: Sudafrica | G21: 2 | L21: 46191 | M21: 0.875 | N21: Suiza | O21: 2-0 | P21: Bosnia | Q21: 2 | V21: 46193 | W21: 0 | X21: Escocia | Y21: 0-2 | Z21: Marruecos | AA21: X | AE21: 75 | AF21: 46203 | AG21: 0.125 | AH21: holanda | AI21: marruecos
B22: 46192 | C22: 0.125 | D22: Mexico | E22: 2-0 | F22: Corea del Sur | G22: x | L22: 46192 | M22: 0 | N22: Canada | O22: 2-1 | P22: Catar | Q22: X | V22: 46193 | W22: 0.10416667 | X22: Brasil | Y22: 3-0 | Z22: Haiti | AA22: X | AE22: 76 | AF22: 46202 | AG22: 0.79166667 | AH22: brasil | AI22: japón
B23: 46198 | C23: 0.125 | D23: Chequia | E23: 2-3 | F23: Mexico | G23: 1 | L23: 46197 | M23: 0.875 | N23: Bosnia | O23: 1-1 | P23: Catar | Q23: 2 | V23: 46198 | W23: 0 | X23: Escocia | Y23: 1-3 | Z23: Brasil | AA23: X | AE23: 77 | AF23: 46203 | AG23: 0.95833333 | AH23: francia | AI23: egipto
B24: 46198 | C24: 0.125 | D24: Sudafrica | E24: 2-0 | F24: Corea del Sur | G24: 2 | L24: 46197 | M24: 0.875 | N24: Suiza | O24: 3-0 | P24: Canada | Q24: X | V24: 46198 | W24: 0 | X24: Marruecos | Y24: 3-1 | Z24: Haiti | AA24: 2 | AE24: 78 | AF24: 46203 | AG24: 0.79166667 | AH24: ecuador | AI24: senegal
AE25: 79 | AF25: 46204 | AG25: 0.041666667 | AH25: mexico | AI25: noruega
AE26: 80 | AF26: 46204 | AG26: 0.75 | AH26: inglaterra | AI26: argelia
B27: Grupo D | E27: Resultado | G27: 1X2 | H27: Ptos | I27: Ptos | L27: Grupo E | O27: Resultado | Q27: 1X2 | R27: Ptos | S27: Ptos | V27: Grupo F | Y27: Resultado | AA27: 1X2 | AB27: Ptos | AC27: Ptos | AE27: 81 | AF27: 46205 | AG27: 0.083333333 | AH27: estados unidos | AI27: catar
B28: 46186 | C28: 0.125 | D28: EEUU | E28: 1-1 | F28: Paraguay | G28: 2 | L28: 46187 | M28: 0.79166667 | N28: Alemania | O28: 3-0 | P28: Curazao | Q28: X | V28: 46187 | W28: 0.91666667 | X28: Paises Bajos | Y28: 3-1 | Z28: Japon | AA28: 2 | AE28: 82 | AF28: 46204 | AG28: 0.91666667 | AH28: belgica | AI28: chequia
B29: 46187 | C29: 0.25 | D29: Australia | E29: 1-2 | F29: Turquia | G29: 1 | L29: 46188 | M29: 0.041666667 | N29: Costa de Marfil | O29: 2-2 | P29: Ecuador | Q29: 2 | V29: 46188 | W29: 0.16666667 | X29: Suecia | Y29: 2-0 | Z29: Tunez | AA29: 2 | AE29: 83 | AF29: 46206 | AG29: 0.041666667 | AH29: colombia | AI29: croacia
B30: 46192 | C30: 0.875 | D30: EEUU | E30: 2-0 | F30: Australia | G30: 2 | L30: 46193 | M30: 0.91666667 | N30: Alemania | O30: 1-0 | P30: Costa de Marfil | Q30: 2 | V30: 46193 | W30: 0.79166667 | X30: Paises Bajos | Y30: 1-1 | Z30: Suecia | AA30: 1 | AE30: 84 | AF30: 46205 | AG30: 0.875 | AH30: españa | AI30: austria
B31: 46193 | C31: 0.20833333 | D31: Turquia | E31: 0-2 | F31: Paraguay | G31: X | L31: 46194 | M31: 0.083333333 | N31: Ecuador | O31: 2-0 | P31: Curazao | Q31: 2 | V31: 46194 | W31: 0.25 | X31: Tunez | Y31: 0-1 | Z31: Japon | AA31: 1 | AE31: 85 | AF31: 46206 | AG31: 0.20833333 | AH31: suiza | AI31: costa marfil
B32: 46199 | C32: 0.16666667 | D32: Turquia | E32: 1-1 | F32: EEUU | G32: 2 | L32: 46198 | M32: 0.91666667 | N32: Curazao | O32: 0-1 | P32: Costa de Marfil | Q32: X | V32: 46199 | W32: 0.041666667 | X32: Japon | Y32: 0-2 | Z32: Suecia | AA32: X | AE32: 86 | AF32: 46207 | AG32: 0 | AH32: argentina | AI32: uruguay
B33: 46199 | C33: 0.16666667 | D33: Paraguay | E33: 2-2 | F33: Australia | G33: 2 | L33: 46198 | M33: 0.91666667 | N33: Ecuador | O33: 2-2 | P33: Alemania | Q33: 2 | V33: 46199 | W33: 0.041666667 | X33: Tunez | Y33: 0-2 | Z33: Paises Bajos | AA33: X | AE33: 87 | AF33: 46207 | AG33: 0.14583333 | AH33: portugal | AI33: panamá
AE34: 88 | AF34: 46206 | AG34: 0.83333333 | AH34: paraguay | AI34: egipto
B36: Grupo G | E36: Resultado | G36: 1X2 | H36: Ptos | I36: Ptos | L36: Grupo H | O36: Resultado | Q36: 1X2 | R36: Ptos | S36: Ptos | V36: Grupo I | Y36: Resultado | AA36: 1X2 | AB36: Ptos | AC36: Ptos | AF36: OCTAVOS
B37: 46188 | C37: 0.875 | D37: Belgica | E37: 2-0 | F37: Egipto | G37: X | L37: 46188 | M37: 0.75 | N37: España | O37: 4-0 | P37: Cabo Verde | Q37: X | V37: 46189 | W37: 0.875 | X37: Francia | Y37: 3-1 | Z37: Senegal | AA37: 2 | AF37: 35ptos/equipo ó 55ptos/equipo+casilla | AJ37: Ptos
B38: 46189 | C38: 0.125 | D38: Iran | E38: 3-2 | F38: Nueva Zelanda | G38: 2 | L38: 46189 | M38: 0 | N38: Arabia Saudi | O38: 0-2 | P38: Uruguay | Q38: X | V38: 46190 | W38: 0 | X38: Irak | Y38: 0-2 | Z38: Noruega | AA38: X | AE38: 89 | AF38: 46207 | AG38: 0.95833333 | AH38: alemania | AI38: francia
B39: 46194 | C39: 0.875 | D39: Belgica | E39: 1-0 | F39: Iran | G39: 2 | L39: 46194 | M39: 0.75 | N39: España | O39: 2-0 | P39: Arabia Saudi | Q39: X | V39: 46195 | W39: 0.95833333 | X39: Francia | Y39: 2-0 | Z39: Irak | AA39: X | AE39: 90 | AF39: 46207 | AG39: 0.79166667 | AH39: bosnia | AI39: marruecos
B40: 46195 | C40: 0.125 | D40: Nueva Zelanda | E40: 2-0 | F40: Egipto | G40: X | L40: 46195 | M40: 0 | N40: Uruguay | O40: 3-1 | P40: Cabo Verde | Q40: X | V40: 46196 | W40: 0.083333333 | X40: Noruega | Y40: 1-2 | Z40: Senegal | AA40: 1 | AE40: 91 | AF40: 46208 | AG40: 0.91666667 | AH40: brasil | AI40: senegal
B41: 46200 | C41: 0.20833333 | D41: Egipto | E41: 1-2 | F41: Iran | G41: X | L41: 46200 | M41: 0.083333333 | N41: Cabo Verde | O41: 1-1 | P41: Arabia Saudi | Q41: 2 | V41: 46199 | W41: 0.875 | X41: Noruega | Y41: 0-2 | Z41: Francia | AA41: X | AE41: 92 | AF41: 46209 | AG41: 0.083333333 | AH41: méxico | AI41: inglaterra
B42: 46200 | C42: 0.20833333 | D42: Nueva Zelanda | E42: 0-2 | F42: Belgica | G42: X | L42: 46200 | M42: 0.083333333 | N42: Uruguay | O42: 2-2 | P42: España | Q42: 2 | V42: 46199 | W42: 0.875 | X42: Senegal | Y42: 1-0 | Z42: Irak | AA42: X | AE42: 93 | AF42: 46209 | AG42: 0.875 | AH42: colombia | AI42: españa
AE43: 94 | AF43: 46210 | AG43: 0.083333333 | AH43: estados unidos | AI43: belgica
AE44: 95 | AF44: 46210 | AG44: 0.75 | AH44: argentina | AI44: egipto
B45: Grupo J | E45: Resultado | G45: 1X2 | H45: Ptos | I45: Ptos | L45: Grupo K | O45: Resultado | Q45: 1X2 | R45: Ptos | S45: Ptos | V45: Grupo L | Y45: Resultado | AA45: 1X2 | AB45: Ptos | AC45: Ptos | AE45: 96 | AF45: 46210 | AG45: 0.91666667 | AH45: suiza | AI45: portugal
B46: 46190 | C46: 0.125 | D46: Argentina | E46: 2-0 | F46: Argelia | G46: X | L46: 46190 | M46: 0.79166667 | N46: Portugal | O46: 3-0 | P46: Congo | Q46: X | V46: 46190 | W46: 0.91666667 | X46: Inglaterra | Y46: 3-1 | Z46: Croacia | AA46: 2
B47: 46190 | C47: 0.25 | D47: Austria | E47: 1-4 | F47: Jordania | G47: X | L47: 46191 | M47: 0.16666667 | N47: Uzbekistan | O47: 0-2 | P47: Colombia | Q47: X | V47: 46191 | W47: 0.041666667 | X47: Ghana | Y47: 0-0 | Z47: Panama | AA47: 2 | AF47: CUARTOS
B48: 46195 | C48: 0.79166667 | D48: Argentina | E48: 2-0 | F48: Austria | G48: 2 | L48: 46196 | M48: 0.79166667 | N48: Portugal | O48: 3-1 | P48: Uzbekistan | Q48: 2 | V48: 46196 | W48: 0.91666667 | X48: Inglaterra | Y48: 1-0 | Z48: Ghana | AA48: 2 | AF48: 50ptos/equipo ó 75ptos/equipo+casilla | AJ48: Ptos
B49: 46196 | C49: 0.20833333 | D49: Jordania | E49: 0-2 | F49: Argelia | G49: X | L49: 46197 | M49: 0.16666667 | N49: Colombia | O49: 1-0 | P49: Congo | Q49: X | V49: 46197 | W49: 0.041666667 | X49: Panama | Y49: 0-2 | Z49: Croacia | AA49: X | AE49: 97 | AF49: 46212 | AG49: 0.91666667 | AH49: francia | AI49: marruecos
B50: 46201 | C50: 0.16666667 | D50: Argelia | E50: 1-1 | F50: Austria | G50: 2 | L50: 46201 | M50: 0.0625 | N50: Colombia | O50: 2-2 | P50: Portugal | Q50: X | V50: 46200 | W50: 0.95833333 | X50: Panama | Y50: 0-2 | Z50: Inglaterra | AA50: X | AE50: 98 | AF50: 46213 | AG50: 0.875 | AH50: españa | AI50: belgica
B51: 46201 | C51: 0.16666667 | D51: Jordania | E51: 0-2 | F51: Argentina | G51: X | L51: 46201 | M51: 0.0625 | N51: Congo | O51: 0-0 | P51: Uzbekistan | Q51: 2 | V51: 46200 | W51: 0.95833333 | X51: Croacia | Y51: 3-0 | Z51: Ghana | AA51: 2 | AE51: 99 | AF51: 46214 | AG51: 0.95833333 | AH51: brasil | AI51: inglaterra
...

Sheet MIGUEL 2
B2: Selección Española | C2: 15puntos | D2: Ptos
B3: Caerá España en penaltis | C3: NO
B4: Se lesionará alguien (lesión, no molestias…) | C4: SI
B5: Anularan a España algun gol por el VAR | C5: SI
B6: Se perderá alguien algún partido por sanción | C6: SI
B7: Marcara Victor Muñoz (no vale penalti) | C7: NO
B8: Luis de la Fuente verá tarjeta? | C8: SI
B9: Jugara algún minuto Yeremy Pino | C9: SI
B10: Jugará otro portero que no sea Unai Simon | C10: SI
C11: 30puntos
B12: Primer tarjeteado | C12: Marcos Llorente
B13: Quien marcará más goles (Victor Muñoz, Borja Iglesias, Yeremy Pino) | C13: Borja Iglesias
B14: Quien marcará más goles (Oyarzabal, Dani Olmo, Yamal) | C14: Oyarzabal
B15: Quien dará más asistencias (Pedri, Yamal, Zubimendi) | C15: Pedri
B16: Quien recibirá más tarjetas amarillas (Cucurella, Pedro Porro, Le Normand) | C16: Cucurella
B17: Primer cambio (primero en salir del campo) | C17: Fabian
B18: Primer cambio (primero en entrar al campo) | C18: Pedro Porro
B19: Cuántos partidos jugará España | C19: 6
C20: 60puntos
B21: Máximo goleador | C21: Oyarzabal
B22: Maximo asistente | C22: Pedri
B23: Cuántos goles marcará España | C23: 12
B24: Cuántos goles le marcarán a España | C24: 6
D25: =SUM(D3:D24) -> 0
B27: Generales | C27: 15puntos | D27: Ptos
B28: Marcara Cristiano de falta | C28: NO
B29: Cuántos 0-0 habrá en la fase de grupos | C29: 6
B30: Primera selección en marcar un gol (no cuenta en propia) | C30: Sudafrica | F30: ALINEACION | G30: =[1]MIGUEL!H72 -> 0
B31: Primera selección en recibir una tarjeta | C31: Sudafrica | F31: PRONÓSTICOS: | G31: =[1]MIGUEL!AB53+[1]MIGUEL!AC53 -> 0
B32: Mayor número de goles que habrá en un partido. Solo 90 min | C32: 8 | F32: GOLES: | G32: =SUM([1]MIGUEL!R60:R64)*40 -> 0
B33: Mayor goleada (diferencia de goles entre los 2 equipos). Solo 90 min | C33: 5 | F33: PORTEROS | G33: =SUM([1]MIGUEL!AA61:AA63)*30+SUM([1]MIGUEL!AB61:AB63)*40 -> 0
C34: 30puntos | F34: PREGUNTAS: | G34: =G59 -> 0
B35: Número de goles del máximo goleador | C35: 8 | F35: PUNTUACIÓN FINAL | G35: =SUM(G28:G34) -> 0
B36: Selección más goleadora | C36: Francia
B37: Selección menos goleada | C37: España
B38: Selección más goleada | C38: Cabo Verde
B39: Selección menos goleadora | C39: Belgica
B40: Primera selección en parar un penalti | C40: Arabia Saudi
B41: Primera selección con un jugador expulsado | C41: Uzbekistan
B42: Acabará alguna selección con 0 puntos | C42: SI
...

Sheet LEO
AF2: Participación: 20 €
K4: MACROPORRA MUNDIAL 2026
K8: Nombre: | M8: Leo
K11: e-mail: | M11: leo.borregas@gmail.com
B14: Guarda el archivo con tu nombre y envíalo a iperezurrutia@gmail.com o por WHATSAPP Fecha límite de envío y de pago: Primer partido Mundial (11/06/2026 21:00)
B16: ESCRIBE UN SIGNO (10 PUNTOS) Y UN RESULTADO (25 PUNTOS)
AF17: DIECISEISAVOS
B18: Grupo A | E18: Resultado | G18: 1X2 | H18: Ptos | I18: Ptos | L18: Grupo B | O18: Resultado | Q18: 1X2 | R18: Ptos | S18: Ptos | V18: Grupo C | Y18: Resultado | AA18: 1X2 | AB18: Ptos | AC18: Ptos | AF18: 20ptos/equipo ó 40ptos/equipo+casilla | AJ18: Ptos
B19: 46184 | C19: 0.875 | D19: Mexico | E19: 1-1 | F19: Sudafrica | G19: X | L19: 46185 | M19: 0.875 | N19: Canada | O19: 2-0 | P19: Bosnia | Q19: 1 | V19: 46187 | W19: 0 | X19: Brasil | Y19: 2-0 | Z19: Marruecos | AA19: 1 | AE19: 73 | AF19: 46201 | AG19: 0.875 | AH19: Chequia | AI19: Canada
B20: 46185 | C20: 0.16666667 | D20: Corea del Sur | E20: 1-2 | F20: Chequia | G20: 2 | L20: 46186 | M20: 0.875 | N20: Catar | O20: 0-3 | P20: Suiza | Q20: 2 | V20: 46187 | W20: 0.125 | X20: Haiti | Y20: 0-3 | Z20: Escocia | AA20: 2 | AE20: 74 | AF20: 46202 | AG20: 0.9375 | AH20: Alemania | AI20: Corea del Sur
B21: 46191 | C21: 0.75 | D21: Chequia | E21: 1-0 | F21: Sudafrica | G21: 1 | L21: 46191 | M21: 0.875 | N21: Suiza | O21: 1-0 | P21: Bosnia | Q21: 1 | V21: 46193 | W21: 0 | X21: Escocia | Y21: 1-2 | Z21: Marruecos | AA21: 2 | AE21: 75 | AF21: 46203 | AG21: 0.125 | AH21: Paises Bajos | AI21: Marruecos
B22: 46192 | C22: 0.125 | D22: Mexico | E22: 2-1 | F22: Corea del Sur | G22: 1 | L22: 46192 | M22: 0 | N22: Canada | O22: 3-1 | P22: Catar | Q22: 1 | V22: 46193 | W22: 0.10416667 | X22: Brasil | Y22: 5-0 | Z22: Haiti | AA22: 1 | AE22: 76 | AF22: 46202 | AG22: 0.79166667 | AH22: Brasil | AI22: Suecia
B23: 46198 | C23: 0.125 | D23: Chequia | E23: 0-0 | F23: Mexico | G23: X | L23: 46197 | M23: 0.875 | N23: Bosnia | O23: 2-1 | P23: Catar | Q23: 1 | V23: 46198 | W23: 0 | X23: Escocia | Y23: 0-2 | Z23: Brasil | AA23: 2 | AE23: 77 | AF23: 46203 | AG23: 0.95833333 | AH23: Francia | AI23: Iran
B24: 46198 | C24: 0.125 | D24: Sudafrica | E24: 1-2 | F24: Corea del Sur | G24: 2 | L24: 46197 | M24: 0.875 | N24: Suiza | O24: 2-2 | P24: Canada | Q24: X | V24: 46198 | W24: 0 | X24: Marruecos | Y24: 4-0 | Z24: Haiti | AA24: 1 | AE24: 78 | AF24: 46203 | AG24: 0.79166667 | AH24: Ecuador | AI24: Noruega
AE25: 79 | AF25: 46204 | AG25: 0.041666667 | AH25: Mexico | AI25: Senegal
AE26: 80 | AF26: 46204 | AG26: 0.75 | AH26: Inglaterra | AI26: Uzbekistan
B27: Grupo D | E27: Resultado | G27: 1X2 | H27: Ptos | I27: Ptos | L27: Grupo E | O27: Resultado | Q27: 1X2 | R27: Ptos | S27: Ptos | V27: Grupo F | Y27: Resultado | AA27: 1X2 | AB27: Ptos | AC27: Ptos | AE27: 81 | AF27: 46205 | AG27: 0.083333333 | AH27: EEUU | AI27: Japon
B28: 46186 | C28: 0.125 | D28: EEUU | E28: 1-0 | F28: Paraguay | G28: 1 | L28: 46187 | M28: 0.79166667 | N28: Alemania | O28: 3-0 | P28: Curazao | Q28: 1 | V28: 46187 | W28: 0.91666667 | X28: Paises Bajos | Y28: 2-1 | Z28: Japon | AA28: 1 | AE28: 82 | AF28: 46204 | AG28: 0.91666667 | AH28: Belgica | AI28: Argelia
B29: 46187 | C29: 0.25 | D29: Australia | E29: 1-2 | F29: Turquia | G29: 2 | L29: 46188 | M29: 0.041666667 | N29: Costa de Marfil | O29: 1-1 | P29: Ecuador | Q29: X | V29: 46188 | W29: 0.16666667 | X29: Suecia | Y29: 1-0 | Z29: Tunez | AA29: 1 | AE29: 83 | AF29: 46206 | AG29: 0.041666667 | AH29: Colombia | AI29: Croacia
B30: 46192 | C30: 0.875 | D30: EEUU | E30: 2-0 | F30: Australia | G30: 1 | L30: 46193 | M30: 0.91666667 | N30: Alemania | O30: 2-1 | P30: Costa de Marfil | Q30: 1 | V30: 46193 | W30: 0.79166667 | X30: Paises Bajos | Y30: 2-0 | Z30: Suecia | AA30: 1 | AE30: 84 | AF30: 46205 | AG30: 0.875 | AH30: España | AI30: Austria
B31: 46193 | C31: 0.20833333 | D31: Turquia | E31: 1-1 | F31: Paraguay | G31: X | L31: 46194 | M31: 0.083333333 | N31: Ecuador | O31: 4-0 | P31: Curazao | Q31: 1 | V31: 46194 | W31: 0.25 | X31: Tunez | Y31: 1-2 | Z31: Japon | AA31: 2 | AE31: 85 | AF31: 46206 | AG31: 0.20833333 | AH31: Suiza | AI31: Ghana
B32: 46199 | C32: 0.16666667 | D32: Turquia | E32: 2-2 | F32: EEUU | G32: X | L32: 46198 | M32: 0.91666667 | N32: Curazao | O32: 1-2 | P32: Costa de Marfil | Q32: 2 | V32: 46199 | W32: 0.041666667 | X32: Japon | Y32: 1-1 | Z32: Suecia | AA32: X | AE32: 86 | AF32: 46207 | AG32: 0 | AH32: Argentina | AI32: Uruguay
B33: 46199 | C33: 0.16666667 | D33: Paraguay | E33: 2-1 | F33: Australia | G33: 1 | L33: 46198 | M33: 0.91666667 | N33: Ecuador | O33: 1-1 | P33: Alemania | Q33: X | V33: 46199 | W33: 0.041666667 | X33: Tunez | Y33: 0-2 | Z33: Paises Bajos | AA33: 2 | AE33: 87 | AF33: 46207 | AG33: 0.14583333 | AH33: Portugal | AI33: Paraguay
AE34: 88 | AF34: 46206 | AG34: 0.83333333 | AH34: Turquia | AI34: Egipto
B36: Grupo G | E36: Resultado | G36: 1X2 | H36: Ptos | I36: Ptos | L36: Grupo H | O36: Resultado | Q36: 1X2 | R36: Ptos | S36: Ptos | V36: Grupo I | Y36: Resultado | AA36: 1X2 | AB36: Ptos | AC36: Ptos | AF36: OCTAVOS
B37: 46188 | C37: 0.875 | D37: Belgica | E37: 2-0 | F37: Egipto | G37: 1 | L37: 46188 | M37: 0.75 | N37: España | O37: 3-0 | P37: Cabo Verde | Q37: 1 | V37: 46189 | W37: 0.875 | X37: Francia | Y37: 2-0 | Z37: Senegal | AA37: 1 | AF37: 35ptos/equipo ó 55ptos/equipo+casilla | AJ37: Ptos
B38: 46189 | C38: 0.125 | D38: Iran | E38: 1-0 | F38: Nueva Zelanda | G38: 1 | L38: 46189 | M38: 0 | N38: Arabia Saudi | O38: 0-2 | P38: Uruguay | Q38: 2 | V38: 46190 | W38: 0 | X38: Irak | Y38: 0-2 | Z38: Noruega | AA38: 2 | AE38: 89 | AF38: 46207 | AG38: 0.95833333 | AH38: Alemania | AI38: Francia
B39: 46194 | C39: 0.875 | D39: Belgica | E39: 3-1 | F39: Iran | G39: 1 | L39: 46194 | M39: 0.75 | N39: España | O39: 2-0 | P39: Arabia Saudi | Q39: 1 | V39: 46195 | W39: 0.95833333 | X39: Francia | Y39: 4-1 | Z39: Irak | AA39: 1 | AE39: 90 | AF39: 46207 | AG39: 0.79166667 | AH39: Canada | AI39: Paises Bajos
B40: 46195 | C40: 0.125 | D40: Nueva Zelanda | E40: 0-1 | F40: Egipto | G40: 2 | L40: 46195 | M40: 0 | N40: Uruguay | O40: 4-0 | P40: Cabo Verde | Q40: 1 | V40: 46196 | W40: 0.083333333 | X40: Noruega | Y40: 1-1 | Z40: Senegal | AA40: X | AE40: 91 | AF40: 46208 | AG40: 0.91666667 | AH40: Brasil | AI40: Ecuador
B41: 46200 | C41: 0.20833333 | D41: Egipto | E41: 1-0 | F41: Iran | G41: 1 | L41: 46200 | M41: 0.083333333 | N41: Cabo Verde | O41: 1-1 | P41: Arabia Saudi | Q41: X | V41: 46199 | W41: 0.875 | X41: Noruega | Y41: 1-2 | Z41: Francia | AA41: 2 | AE41: 92 | AF41: 46209 | AG41: 0.083333333 | AH41: Mexico | AI41: Inglaterra
B42: 46200 | C42: 0.20833333 | D42: Nueva Zelanda | E42: 0-3 | F42: Belgica | G42: 2 | L42: 46200 | M42: 0.083333333 | N42: Uruguay | O42: 1-2 | P42: España | Q42: 2 | V42: 46199 | W42: 0.875 | X42: Senegal | Y42: 2-0 | Z42: Irak | AA42: 1 | AE42: 93 | AF42: 46209 | AG42: 0.875 | AH42: Colombia | AI42: España
AE43: 94 | AF43: 46210 | AG43: 0.083333333 | AH43: EEUU | AI43: Belgica
AE44: 95 | AF44: 46210 | AG44: 0.75 | AH44: Argentina | AI44: Turquia
B45: Grupo J | E45: Resultado | G45: 1X2 | H45: Ptos | I45: Ptos | L45: Grupo K | O45: Resultado | Q45: 1X2 | R45: Ptos | S45: Ptos | V45: Grupo L | Y45: Resultado | AA45: 1X2 | AB45: Ptos | AC45: Ptos | AE45: 96 | AF45: 46210 | AG45: 0.91666667 | AH45: Suiza | AI45: Portugal
B46: 46190 | C46: 0.125 | D46: Argentina | E46: 2-0 | F46: Argelia | G46: 1 | L46: 46190 | M46: 0.79166667 | N46: Portugal | O46: 4-0 | P46: Congo | Q46: 1 | V46: 46190 | W46: 0.91666667 | X46: Inglaterra | Y46: 1-1 | Z46: Croacia | AA46: X
B47: 46190 | C47: 0.25 | D47: Austria | E47: 2-1 | F47: Jordania | G47: 1 | L47: 46191 | M47: 0.16666667 | N47: Uzbekistan | O47: 0-2 | P47: Colombia | Q47: 2 | V47: 46191 | W47: 0.041666667 | X47: Ghana | Y47: 2-1 | Z47: Panama | AA47: 1 | AF47: CUARTOS
B48: 46195 | C48: 0.79166667 | D48: Argentina | E48: 1-0 | F48: Austria | G48: 1 | L48: 46196 | M48: 0.79166667 | N48: Portugal | O48: 3-1 | P48: Uzbekistan | Q48: 1 | V48: 46196 | W48: 0.91666667 | X48: Inglaterra | Y48: 2-0 | Z48: Ghana | AA48: 1 | AF48: 50ptos/equipo ó 75ptos/equipo+casilla | AJ48: Ptos
B49: 46196 | C49: 0.20833333 | D49: Jordania | E49: 1-2 | F49: Argelia | G49: 2 | L49: 46197 | M49: 0.16666667 | N49: Colombia | O49: 3-0 | P49: Congo | Q49: 1 | V49: 46197 | W49: 0.041666667 | X49: Panama | Y49: 0-2 | Z49: Croacia | AA49: 2 | AE49: 97 | AF49: 46212 | AG49: 0.91666667 | AH49: Francia | AI49: Paises Bajos
B50: 46201 | C50: 0.16666667 | D50: Argelia | E50: 1-1 | F50: Austria | G50: X | L50: 46201 | M50: 0.0625 | N50: Colombia | O50: 2-2 | P50: Portugal | Q50: X | V50: 46200 | W50: 0.95833333 | X50: Panama | Y50: 0-3 | Z50: Inglaterra | AA50: 2 | AE50: 98 | AF50: 46213 | AG50: 0.875 | AH50: España | AI50: Belgica
B51: 46201 | C51: 0.16666667 | D51: Jordania | E51: 0-3 | F51: Argentina | G51: 2 | L51: 46201 | M51: 0.0625 | N51: Congo | O51: 0-1 | P51: Uzbekistan | Q51: 2 | V51: 46200 | W51: 0.95833333 | X51: Croacia | Y51: 2-1 | Z51: Ghana | AA51: 1 | AE51: 99 | AF51: 46214 | AG51: 0.95833333 | AH51: Brasil | AI51: Inglaterra
...

Sheet LEO 2
B2: Selección Española | C2: 15puntos | D2: Ptos
B3: Caerá España en penaltis | C3: NO
B4: Se lesionará alguien (lesión, no molestias…) | C4: SI
B5: Anularan a España algun gol por el VAR | C5: SI
B6: Se perderá alguien algún partido por sanción | C6: SI
B7: Marcara Victor Muñoz (no vale penalti) | C7: NO
B8: Luis de la Fuente verá tarjeta? | C8: NO
B9: Jugara algún minuto Yeremy Pino | C9: SI
B10: Jugará otro portero que no sea Unai Simon | C10: SI
C11: 30puntos
B12: Primer tarjeteado | C12: Cucurella
B13: Quien marcará más goles (Victor Muñoz, Borja Iglesias, Yeremy Pino) | C13: Yeremy Pino
B14: Quien marcará más goles (Oyarzabal, Dani Olmo, Yamal) | C14: Oyarzabal
B15: Quien dará más asistencias (Pedri, Yamal, Zubimendi) | C15: Yamal
B16: Quien recibirá más tarjetas amarillas (Cucurella, Pedro Porro, Le Normand) | C16: Cucurella
B17: Primer cambio (primero en salir del campo) | C17: Dani Olmo
B18: Primer cambio (primero en entrar al campo) | C18: Alex Baena
B19: Cuántos partidos jugará España | C19: 7
C20: 60puntos
B21: Máximo goleador | C21: Oyarzabal
B22: Maximo asistente | C22: Yamal
B23: Cuántos goles marcará España | C23: 17
B24: Cuántos goles le marcarán a España | C24: 5
D25: =SUM(D3:D24) -> 0
B27: Generales | C27: 15puntos | D27: Ptos
B28: Marcara Cristiano de falta | C28: SI
B29: Cuántos 0-0 habrá en la fase de grupos | C29: 4
B30: Primera selección en marcar un gol (no cuenta en propia) | C30: Mexico | F30: ALINEACION | G30: =[2]LEO!H72 -> 0
B31: Primera selección en recibir una tarjeta | C31: Sudafrica | F31: PRONÓSTICOS: | G31: =[2]LEO!AB53+[2]LEO!AC53 -> 0
B32: Mayor número de goles que habrá en un partido. Solo 90 min | C32: 5 | F32: GOLES: | G32: =SUM([2]LEO!R60:R64)*40 -> 0
B33: Mayor goleada (diferencia de goles entre los 2 equipos). Solo 90 min | C33: 5 | F33: PORTEROS | G33: =SUM([2]LEO!AA61:AA63)*30+SUM([2]LEO!AB61:AB63)*40 -> 0
C34: 30puntos | F34: PREGUNTAS: | G34: =G59 -> 0
B35: Número de goles del máximo goleador | C35: 8 | F35: PUNTUACIÓN FINAL | G35: =SUM(G28:G34) -> 0
B36: Selección más goleadora | C36: Francia
B37: Selección menos goleada | C37: España
B38: Selección más goleada | C38: Haití
B39: Selección menos goleadora | C39: Congo
B40: Primera selección en parar un penalti | C40: Portugal
B41: Primera selección con un jugador expulsado | C41: Paraguay
B42: Acabará alguna selección con 0 puntos | C42: SI
...

Sheet VIK
AF2: Participación: 20 €
K4: MACROPORRA MUNDIAL 2026
K8: Nombre: | M8: Víctor Concejero Sanz (Vik, Vconce)
K11: e-mail: | M11: vconces@gmail.com
B14: Guarda el archivo con tu nombre y envíalo a iperezurrutia@gmail.com o por WHATSAPP Fecha límite de envío y de pago: Primer partido Mundial (11/06/2026 21:00)
B16: ESCRIBE UN SIGNO (10 PUNTOS) Y UN RESULTADO (25 PUNTOS)
AF17: DIECISEISAVOS
B18: Grupo A | E18: Resultado | G18: 1X2 | H18: Ptos | I18: Ptos | L18: Grupo B | O18: Resultado | Q18: 1X2 | R18: Ptos | S18: Ptos | V18: Grupo C | Y18: Resultado | AA18: 1X2 | AB18: Ptos | AC18: Ptos | AF18: 20ptos/equipo ó 40ptos/equipo+casilla | AJ18: Ptos
B19: 46184 | C19: 0.875 | D19: Mexico | E19: 2-0 | F19: Sudafrica | G19: 1 | L19: 46185 | M19: 0.875 | N19: Canada | O19: 1-1 | P19: Bosnia | Q19: X | V19: 46187 | W19: 0 | X19: Brasil | Y19: 2-1 | Z19: Marruecos | AA19: 1 | AE19: 73 | AF19: 46201 | AG19: 0.875 | AH19: Corea del Sur | AI19: Canada
B20: 46185 | C20: 0.16666667 | D20: Corea del Sur | E20: 2-1 | F20: Chequia | G20: 1 | L20: 46186 | M20: 0.875 | N20: Catar | O20: 0-2 | P20: Suiza | Q20: 2 | V20: 46187 | W20: 0.125 | X20: Haiti | Y20: 0-2 | Z20: Escocia | AA20: 2 | AE20: 74 | AF20: 46202 | AG20: 0.9375 | AH20: Alemania | AI20: Paraguay
B21: 46191 | C21: 0.75 | D21: Chequia | E21: 2-0 | F21: Sudafrica | G21: 1 | L21: 46191 | M21: 0.875 | N21: Suiza | O21: 2-0 | P21: Bosnia | Q21: 1 | V21: 46193 | W21: 0 | X21: Escocia | Y21: 1-2 | Z21: Marruecos | AA21: 2 | AE21: 75 | AF21: 46203 | AG21: 0.125 | AH21: Paises Bajos | AI21: Marruecos
B22: 46192 | C22: 0.125 | D22: Mexico | E22: 1-1 | F22: Corea del Sur | G22: X | L22: 46192 | M22: 0 | N22: Canada | O22: 2-1 | P22: Catar | Q22: 1 | V22: 46193 | W22: 0.10416667 | X22: Brasil | Y22: 4-0 | Z22: Haiti | AA22: 1 | AE22: 76 | AF22: 46202 | AG22: 0.79166667 | AH22: Brasil | AI22: Japon
B23: 46198 | C23: 0.125 | D23: Chequia | E23: 1-2 | F23: Mexico | G23: 2 | L23: 46197 | M23: 0.875 | N23: Bosnia | O23: 1-0 | P23: Catar | Q23: 1 | V23: 46198 | W23: 0 | X23: Escocia | Y23: 0-2 | Z23: Brasil | AA23: 2 | AE23: 77 | AF23: 46203 | AG23: 0.95833333 | AH23: Francia | AI23: Suecia
B24: 46198 | C24: 0.125 | D24: Sudafrica | E24: 0-2 | F24: Corea del Sur | G24: 2 | L24: 46197 | M24: 0.875 | N24: Suiza | O24: 2-1 | P24: Canada | Q24: 1 | V24: 46198 | W24: 0 | X24: Marruecos | Y24: 2-0 | Z24: Haiti | AA24: 1 | AE24: 78 | AF24: 46203 | AG24: 0.79166667 | AH24: Ecuador | AI24: Noruega
AE25: 79 | AF25: 46204 | AG25: 0.041666667 | AH25: Mexico | AI25: Senegal
AE26: 80 | AF26: 46204 | AG26: 0.75 | AH26: Inglaterra | AI26: Argelia
B27: Grupo D | E27: Resultado | G27: 1X2 | H27: Ptos | I27: Ptos | L27: Grupo E | O27: Resultado | Q27: 1X2 | R27: Ptos | S27: Ptos | V27: Grupo F | Y27: Resultado | AA27: 1X2 | AB27: Ptos | AC27: Ptos | AE27: 81 | AF27: 46205 | AG27: 0.083333333 | AH27: EEUU | AI27: Bosnia
B28: 46186 | C28: 0.125 | D28: EEUU | E28: 2-1 | F28: Paraguay | G28: 1 | L28: 46187 | M28: 0.79166667 | N28: Alemania | O28: 4-0 | P28: Curazao | Q28: 1 | V28: 46187 | W28: 0.91666667 | X28: Paises Bajos | Y28: 2-1 | Z28: Japon | AA28: 1 | AE28: 82 | AF28: 46204 | AG28: 0.91666667 | AH28: Belgica | AI28: Costa de Marfil
B29: 46187 | C29: 0.25 | D29: Australia | E29: 0-2 | F29: Turquia | G29: 2 | L29: 46188 | M29: 0.041666667 | N29: Costa de Marfil | O29: 1-2 | P29: Ecuador | Q29: 2 | V29: 46188 | W29: 0.16666667 | X29: Suecia | Y29: 1-0 | Z29: Tunez | AA29: 1 | AE29: 83 | AF29: 46206 | AG29: 0.041666667 | AH29: Colombia | AI29: Croacia
B30: 46192 | C30: 0.875 | D30: EEUU | E30: 2-0 | F30: Australia | G30: 1 | L30: 46193 | M30: 0.91666667 | N30: Alemania | O30: 2-1 | P30: Costa de Marfil | Q30: 1 | V30: 46193 | W30: 0.79166667 | X30: Paises Bajos | Y30: 2-1 | Z30: Suecia | AA30: 1 | AE30: 84 | AF30: 46205 | AG30: 0.875 | AH30: España | AI30: Austria
B31: 46193 | C31: 0.20833333 | D31: Turquia | E31: 1-1 | F31: Paraguay | G31: X | L31: 46194 | M31: 0.083333333 | N31: Ecuador | O31: 3-0 | P31: Curazao | Q31: 1 | V31: 46194 | W31: 0.25 | X31: Tunez | Y31: 0-2 | Z31: Japon | AA31: 2 | AE31: 85 | AF31: 46206 | AG31: 0.20833333 | AH31: Suiza | AI31: Iran
B32: 46199 | C32: 0.16666667 | D32: Turquia | E32: 1-1 | F32: EEUU | G32: X | L32: 46198 | M32: 0.91666667 | N32: Curazao | O32: 0-2 | P32: Costa de Marfil | Q32: 2 | V32: 46199 | W32: 0.041666667 | X32: Japon | Y32: 1-1 | Z32: Suecia | AA32: X | AE32: 86 | AF32: 46207 | AG32: 0 | AH32: Argentina | AI32: Uruguay
B33: 46199 | C33: 0.16666667 | D33: Paraguay | E33: 2-1 | F33: Australia | G33: 1 | L33: 46198 | M33: 0.91666667 | N33: Ecuador | O33: 1-1 | P33: Alemania | Q33: X | V33: 46199 | W33: 0.041666667 | X33: Tunez | Y33: 0-2 | Z33: Paises Bajos | AA33: 2 | AE33: 87 | AF33: 46207 | AG33: 0.14583333 | AH33: Portugal | AI33: Ghana
AE34: 88 | AF34: 46206 | AG34: 0.83333333 | AH34: Turquia | AI34: Egipto
B36: Grupo G | E36: Resultado | G36: 1X2 | H36: Ptos | I36: Ptos | L36: Grupo H | O36: Resultado | Q36: 1X2 | R36: Ptos | S36: Ptos | V36: Grupo I | Y36: Resultado | AA36: 1X2 | AB36: Ptos | AC36: Ptos | AF36: OCTAVOS
B37: 46188 | C37: 0.875 | D37: Belgica | E37: 2-0 | F37: Egipto | G37: 1 | L37: 46188 | M37: 0.75 | N37: España | O37: 3-0 | P37: Cabo Verde | Q37: 1 | V37: 46189 | W37: 0.875 | X37: Francia | Y37: 2-1 | Z37: Senegal | AA37: 1 | AF37: 35ptos/equipo ó 55ptos/equipo+casilla | AJ37: Ptos
B38: 46189 | C38: 0.125 | D38: Iran | E38: 1-0 | F38: Nueva Zelanda | G38: 1 | L38: 46189 | M38: 0 | N38: Arabia Saudi | O38: 0-2 | P38: Uruguay | Q38: 2 | V38: 46190 | W38: 0 | X38: Irak | Y38: 0-3 | Z38: Noruega | AA38: 2 | AE38: 89 | AF38: 46207 | AG38: 0.95833333 | AH38: Alemania | AI38: Francia
B39: 46194 | C39: 0.875 | D39: Belgica | E39: 2-0 | F39: Iran | G39: 1 | L39: 46194 | M39: 0.75 | N39: España | O39: 2-0 | P39: Arabia Saudi | Q39: 1 | V39: 46195 | W39: 0.95833333 | X39: Francia | Y39: 4-0 | Z39: Irak | AA39: 1 | AE39: 90 | AF39: 46207 | AG39: 0.79166667 | AH39: Canada | AI39: Paises Bajos
B40: 46195 | C40: 0.125 | D40: Nueva Zelanda | E40: 0-1 | F40: Egipto | G40: 2 | L40: 46195 | M40: 0 | N40: Uruguay | O40: 2-0 | P40: Cabo Verde | Q40: 1 | V40: 46196 | W40: 0.083333333 | X40: Noruega | Y40: 2-1 | Z40: Senegal | AA40: 1 | AE40: 91 | AF40: 46208 | AG40: 0.91666667 | AH40: Brasil | AI40: Noruega
B41: 46200 | C41: 0.20833333 | D41: Egipto | E41: 1-1 | F41: Iran | G41: X | L41: 46200 | M41: 0.083333333 | N41: Cabo Verde | O41: 1-1 | P41: Arabia Saudi | Q41: X | V41: 46199 | W41: 0.875 | X41: Noruega | Y41: 1-2 | Z41: Francia | AA41: 2 | AE41: 92 | AF41: 46209 | AG41: 0.083333333 | AH41: Mexico | AI41: Inglaterra
B42: 46200 | C42: 0.20833333 | D42: Nueva Zelanda | E42: 0-3 | F42: Belgica | G42: 2 | L42: 46200 | M42: 0.083333333 | N42: Uruguay | O42: 1-2 | P42: España | Q42: 2 | V42: 46199 | W42: 0.875 | X42: Senegal | Y42: 2-0 | Z42: Irak | AA42: 1 | AE42: 93 | AF42: 46209 | AG42: 0.875 | AH42: Colombia | AI42: España
AE43: 94 | AF43: 46210 | AG43: 0.083333333 | AH43: EEUU | AI43: Belgica
AE44: 95 | AF44: 46210 | AG44: 0.75 | AH44: Argentina | AI44: Turquia
B45: Grupo J | E45: Resultado | G45: 1X2 | H45: Ptos | I45: Ptos | L45: Grupo K | O45: Resultado | Q45: 1X2 | R45: Ptos | S45: Ptos | V45: Grupo L | Y45: Resultado | AA45: 1X2 | AB45: Ptos | AC45: Ptos | AE45: 96 | AF45: 46210 | AG45: 0.91666667 | AH45: Suiza | AI45: Portugal
B46: 46190 | C46: 0.125 | D46: Argentina | E46: 2-0 | F46: Argelia | G46: 1 | L46: 46190 | M46: 0.79166667 | N46: Portugal | O46: 3-0 | P46: Congo | Q46: 1 | V46: 46190 | W46: 0.91666667 | X46: Inglaterra | Y46: 2-1 | Z46: Croacia | AA46: 1
B47: 46190 | C47: 0.25 | D47: Austria | E47: 2-0 | F47: Jordania | G47: 1 | L47: 46191 | M47: 0.16666667 | N47: Uzbekistan | O47: 0-2 | P47: Colombia | Q47: 2 | V47: 46191 | W47: 0.041666667 | X47: Ghana | Y47: 1-0 | Z47: Panama | AA47: 1 | AF47: CUARTOS
B48: 46195 | C48: 0.79166667 | D48: Argentina | E48: 2-1 | F48: Austria | G48: 1 | L48: 46196 | M48: 0.79166667 | N48: Portugal | O48: 2-0 | P48: Uzbekistan | Q48: 1 | V48: 46196 | W48: 0.91666667 | X48: Inglaterra | Y48: 2-0 | Z48: Ghana | AA48: 1 | AF48: 50ptos/equipo ó 75ptos/equipo+casilla | AJ48: Ptos
B49: 46196 | C49: 0.20833333 | D49: Jordania | E49: 0-1 | F49: Argelia | G49: 2 | L49: 46197 | M49: 0.16666667 | N49: Colombia | O49: 2-0 | P49: Congo | Q49: 1 | V49: 46197 | W49: 0.041666667 | X49: Panama | Y49: 0-2 | Z49: Croacia | AA49: 2 | AE49: 97 | AF49: 46212 | AG49: 0.91666667 | AH49: Francia | AI49: Paises Bajos
B50: 46201 | C50: 0.16666667 | D50: Argelia | E50: 1-1 | F50: Austria | G50: X | L50: 46201 | M50: 0.0625 | N50: Colombia | O50: 1-1 | P50: Portugal | Q50: X | V50: 46200 | W50: 0.95833333 | X50: Panama | Y50: 0-3 | Z50: Inglaterra | AA50: 2 | AE50: 98 | AF50: 46213 | AG50: 0.875 | AH50: España | AI50: Belgica
B51: 46201 | C51: 0.16666667 | D51: Jordania | E51: 0-3 | F51: Argentina | G51: 2 | L51: 46201 | M51: 0.0625 | N51: Congo | O51: 0-1 | P51: Uzbekistan | Q51: 2 | V51: 46200 | W51: 0.95833333 | X51: Croacia | Y51: 1-1 | Z51: Ghana | AA51: X | AE51: 99 | AF51: 46214 | AG51: 0.95833333 | AH51: Brasil | AI51: Inglaterra
...

Sheet VIK 2
B2: Selección Española | C2: 15puntos | D2: Ptos
B3: Caerá España en penaltis | C3: NO
B4: Se lesionará alguien (lesión, no molestias…) | C4: SI
B5: Anularan a España algun gol por el VAR | C5: SI
B6: Se perderá alguien algún partido por sanción | C6: SI
B7: Marcara Victor Muñoz (no vale penalti) | C7: NO
B8: Luis de la Fuente verá tarjeta? | C8: NO
B9: Jugara algún minuto Yeremy Pino | C9: SI
B10: Jugará otro portero que no sea Unai Simon | C10: SI
C11: 30puntos
B12: Primer tarjeteado | C12: Cucurella
B13: Quien marcará más goles (Victor Muñoz, Borja Iglesias, Yeremy Pino) | C13: Borja Iglesias
B14: Quien marcará más goles (Oyarzabal, Dani Olmo, Yamal) | C14: Oyarzabal
B15: Quien dará más asistencias (Pedri, Yamal, Zubimendi) | C15: Pedri
B16: Quien recibirá más tarjetas amarillas (Cucurella, Pedro Porro, Le Normand) | C16: Cucurella
B17: Primer cambio (primero en salir del campo) | C17: Ferran
B18: Primer cambio (primero en entrar al campo) | C18: Yamal
B19: Cuántos partidos jugará España | C19: 7
C20: 60puntos
B21: Máximo goleador | C21: Oyarzabal
B22: Maximo asistente | C22: Pedri
B23: Cuántos goles marcará España | C23: 16
B24: Cuántos goles le marcarán a España | C24: 6
D25: =SUM(D3:D24) -> 0
B27: Generales | C27: 15puntos | D27: Ptos
B28: Marcara Cristiano de falta | C28: NO
B29: Cuántos 0-0 habrá en la fase de grupos | C29: 2
B30: Primera selección en marcar un gol (no cuenta en propia) | C30: Mexico | F30: ALINEACION | G30: =[3]VIK!H72 -> 0
B31: Primera selección en recibir una tarjeta | C31: Sudafrica | F31: PRONÓSTICOS: | G31: =[3]VIK!AB53+[3]VIK!AC53 -> 0
B32: Mayor número de goles que habrá en un partido. Solo 90 min | C32: 5 | F32: GOLES: | G32: =SUM([3]VIK!R60:R64)*40 -> 0
B33: Mayor goleada (diferencia de goles entre los 2 equipos). Solo 90 min | C33: 4 | F33: PORTEROS | G33: =SUM([3]VIK!AA61:AA63)*30+SUM([3]VIK!AB61:AB63)*40 -> 0
C34: 30puntos | F34: PREGUNTAS: | G34: =G59 -> 0
B35: Número de goles del máximo goleador | C35: 7 | F35: PUNTUACIÓN FINAL | G35: =SUM(G28:G34) -> 0
B36: Selección más goleadora | C36: España
B37: Selección menos goleada | C37: Brasil
B38: Selección más goleada | C38: Haiti
B39: Selección menos goleadora | C39: Curazao
B40: Primera selección en parar un penalti | C40: España
B41: Primera selección con un jugador expulsado | C41: Iran
B42: Acabará alguna selección con 0 puntos | C42: SI
...

Sheet RAMON
AF2: Participación: 20 €
K4: MACROPORRA MUNDIAL 2026
K8: Nombre: | M8: Ramón Lema
K11: e-mail: | M11: ramonlema2001@gmail.com
B14: Guarda el archivo con tu nombre y envíalo a iperezurrutia@gmail.com o por WHATSAPP Fecha límite de envío y de pago: Primer partido Mundial (11/06/2026 21:00)
B16: ESCRIBE UN SIGNO (10 PUNTOS) Y UN RESULTADO (25 PUNTOS)
AF17: DIECISEISAVOS
B18: Grupo A | E18: Resultado | G18: 1X2 | H18: Ptos | I18: Ptos | L18: Grupo B | O18: Resultado | Q18: 1X2 | R18: Ptos | S18: Ptos | V18: Grupo C | Y18: Resultado | AA18: 1X2 | AB18: Ptos | AC18: Ptos | AF18: 20ptos/equipo ó 40ptos/equipo+casilla | AJ18: Ptos
B19: 46184 | C19: 0.875 | D19: Mexico | E19: 2-0 | F19: Sudafrica | G19: 1 | L19: 46185 | M19: 0.875 | N19: Canada | O19: 1-1 | P19: Bosnia | Q19: X | V19: 46187 | W19: 0 | X19: Brasil | Y19: 2-0 | Z19: Marruecos | AA19: 1 | AE19: 73 | AF19: 46201 | AG19: 0.875 | AH19: Chequia | AI19: Canada
B20: 46185 | C20: 0.16666667 | D20: Corea del Sur | E20: 1-1 | F20: Chequia | G20: X | L20: 46186 | M20: 0.875 | N20: Catar | O20: 0-3 | P20: Suiza | Q20: 2 | V20: 46187 | W20: 0.125 | X20: Haiti | Y20: 0-3 | Z20: Escocia | AA20: 2 | AE20: 74 | AF20: 46202 | AG20: 0.9375 | AH20: Alemania | AI20: Marruecos
B21: 46191 | C21: 0.75 | D21: Chequia | E21: 1-0 | F21: Sudafrica | G21: 1 | L21: 46191 | M21: 0.875 | N21: Suiza | O21: 1-0 | P21: Bosnia | Q21: 1 | V21: 46193 | W21: 0 | X21: Escocia | Y21: 0-0 | Z21: Marruecos | AA21: X | AE21: 75 | AF21: 46203 | AG21: 0.125 | AH21: Paises Bajos | AI21: Escocia
B22: 46192 | C22: 0.125 | D22: Mexico | E22: 2-1 | F22: Corea del Sur | G22: 1 | L22: 46192 | M22: 0 | N22: Canada | O22: 2-1 | P22: Catar | Q22: 1 | V22: 46193 | W22: 0.10416667 | X22: Brasil | Y22: 4-0 | Z22: Haiti | AA22: 1 | AE22: 76 | AF22: 46202 | AG22: 0.79166667 | AH22: Brasil | AI22: Suecia
B23: 46198 | C23: 0.125 | D23: Chequia | E23: 0-0 | F23: Mexico | G23: X | L23: 46197 | M23: 0.875 | N23: Bosnia | O23: 1-1 | P23: Catar | Q23: X | V23: 46198 | W23: 0 | X23: Escocia | Y23: 0-1 | Z23: Brasil | AA23: 2 | AE23: 77 | AF23: 46203 | AG23: 0.95833333 | AH23: Francia | AI23: Paraguay
B24: 46198 | C24: 0.125 | D24: Sudafrica | E24: 2-3 | F24: Corea del Sur | G24: 2 | L24: 46197 | M24: 0.875 | N24: Suiza | O24: 2-1 | P24: Canada | Q24: 1 | V24: 46198 | W24: 0 | X24: Marruecos | Y24: 3-0 | Z24: Haiti | AA24: 1 | AE24: 78 | AF24: 46203 | AG24: 0.79166667 | AH24: Ecuador | AI24: Senegal
AE25: 79 | AF25: 46204 | AG25: 0.041666667 | AH25: Mexico | AI25: Arabia Saudi
AE26: 80 | AF26: 46204 | AG26: 0.75 | AH26: Inglaterra | AI26: Noruega
B27: Grupo D | E27: Resultado | G27: 1X2 | H27: Ptos | I27: Ptos | L27: Grupo E | O27: Resultado | Q27: 1X2 | R27: Ptos | S27: Ptos | V27: Grupo F | Y27: Resultado | AA27: 1X2 | AB27: Ptos | AC27: Ptos | AE27: 81 | AF27: 46205 | AG27: 0.083333333 | AH27: Turquia | AI27: Japon
B28: 46186 | C28: 0.125 | D28: EEUU | E28: 2-1 | F28: Paraguay | G28: 1 | L28: 46187 | M28: 0.79166667 | N28: Alemania | O28: 7-0 | P28: Curazao | Q28: 1 | V28: 46187 | W28: 0.91666667 | X28: Paises Bajos | Y28: 2-0 | Z28: Japon | AA28: 1 | AE28: 82 | AF28: 46204 | AG28: 0.91666667 | AH28: Belgica | AI28: Corea del Sur
B29: 46187 | C29: 0.25 | D29: Australia | E29: 0-2 | F29: Turquia | G29: 2 | L29: 46188 | M29: 0.041666667 | N29: Costa de Marfil | O29: 0-2 | P29: Ecuador | Q29: 2 | V29: 46188 | W29: 0.16666667 | X29: Suecia | Y29: 1-0 | Z29: Tunez | AA29: 1 | AE29: 83 | AF29: 46206 | AG29: 0.041666667 | AH29: Colombia | AI29: Croacia
B30: 46192 | C30: 0.875 | D30: EEUU | E30: 3-1 | F30: Australia | G30: 1 | L30: 46193 | M30: 0.91666667 | N30: Alemania | O30: 3-0 | P30: Costa de Marfil | Q30: 1 | V30: 46193 | W30: 0.79166667 | X30: Paises Bajos | Y30: 2-1 | Z30: Suecia | AA30: 1 | AE30: 84 | AF30: 46205 | AG30: 0.875 | AH30: España | AI30: Austria
B31: 46193 | C31: 0.20833333 | D31: Turquia | E31: 2-2 | F31: Paraguay | G31: X | L31: 46194 | M31: 0.083333333 | N31: Ecuador | O31: 3-0 | P31: Curazao | Q31: 1 | V31: 46194 | W31: 0.25 | X31: Tunez | Y31: 1-2 | Z31: Japon | AA31: 2 | AE31: 85 | AF31: 46206 | AG31: 0.20833333 | AH31: Suiza | AI31: Egipto
B32: 46199 | C32: 0.16666667 | D32: Turquia | E32: 3-2 | F32: EEUU | G32: 1 | L32: 46198 | M32: 0.91666667 | N32: Curazao | O32: 0-2 | P32: Costa de Marfil | Q32: 2 | V32: 46199 | W32: 0.041666667 | X32: Japon | Y32: 2-2 | Z32: Suecia | AA32: X | AE32: 86 | AF32: 46207 | AG32: 0 | AH32: Argentina | AI32: Uruguay
B33: 46199 | C33: 0.16666667 | D33: Paraguay | E33: 2-0 | F33: Australia | G33: 1 | L33: 46198 | M33: 0.91666667 | N33: Ecuador | O33: 1-2 | P33: Alemania | Q33: 2 | V33: 46199 | W33: 0.041666667 | X33: Tunez | Y33: 0-2 | Z33: Paises Bajos | AA33: 2 | AE33: 87 | AF33: 46207 | AG33: 0.14583333 | AH33: Portugal | AI33: Ghana
AE34: 88 | AF34: 46206 | AG34: 0.83333333 | AH34: EEUU | AI34: Iran
B36: Grupo G | E36: Resultado | G36: 1X2 | H36: Ptos | I36: Ptos | L36: Grupo H | O36: Resultado | Q36: 1X2 | R36: Ptos | S36: Ptos | V36: Grupo I | Y36: Resultado | AA36: 1X2 | AB36: Ptos | AC36: Ptos | AF36: OCTAVOS
B37: 46188 | C37: 0.875 | D37: Belgica | E37: 1-0 | F37: Egipto | G37: 1 | L37: 46188 | M37: 0.75 | N37: España | O37: 4-0 | P37: Cabo Verde | Q37: 1 | V37: 46189 | W37: 0.875 | X37: Francia | Y37: 3-1 | Z37: Senegal | AA37: 1 | AF37: 35ptos/equipo ó 55ptos/equipo+casilla | AJ37: Ptos
B38: 46189 | C38: 0.125 | D38: Iran | E38: 3-0 | F38: Nueva Zelanda | G38: 1 | L38: 46189 | M38: 0 | N38: Arabia Saudi | O38: 1-1 | P38: Uruguay | Q38: X | V38: 46190 | W38: 0 | X38: Irak | Y38: 1-4 | Z38: Noruega | AA38: 2 | AE38: 89 | AF38: 46207 | AG38: 0.95833333 | AH38: Alemania | AI38: Francia
B39: 46194 | C39: 0.875 | D39: Belgica | E39: 2-1 | F39: Iran | G39: 1 | L39: 46194 | M39: 0.75 | N39: España | O39: 1-0 | P39: Arabia Saudi | Q39: 1 | V39: 46195 | W39: 0.95833333 | X39: Francia | Y39: 3-0 | Z39: Irak | AA39: 1 | AE39: 90 | AF39: 46207 | AG39: 0.79166667 | AH39: Chequia | AI39: Países Bajos
B40: 46195 | C40: 0.125 | D40: Nueva Zelanda | E40: 0-2 | F40: Egipto | G40: 2 | L40: 46195 | M40: 0 | N40: Uruguay | O40: 3-0 | P40: Cabo Verde | Q40: 1 | V40: 46196 | W40: 0.083333333 | X40: Noruega | Y40: 2-2 | Z40: Senegal | AA40: X | AE40: 91 | AF40: 46208 | AG40: 0.91666667 | AH40: Brasil | AI40: Ecuador
B41: 46200 | C41: 0.20833333 | D41: Egipto | E41: 1-1 | F41: Iran | G41: X | L41: 46200 | M41: 0.083333333 | N41: Cabo Verde | O41: 0-2 | P41: Arabia Saudi | Q41: 2 | V41: 46199 | W41: 0.875 | X41: Noruega | Y41: 0-2 | Z41: Francia | AA41: 2 | AE41: 92 | AF41: 46209 | AG41: 0.083333333 | AH41: México | AI41: Inglaterra
B42: 46200 | C42: 0.20833333 | D42: Nueva Zelanda | E42: 0-3 | F42: Belgica | G42: 2 | L42: 46200 | M42: 0.083333333 | N42: Uruguay | O42: 0-1 | P42: España | Q42: 2 | V42: 46199 | W42: 0.875 | X42: Senegal | Y42: 1-0 | Z42: Irak | AA42: 1 | AE42: 93 | AF42: 46209 | AG42: 0.875 | AH42: Colombia | AI42: España
AE43: 94 | AF43: 46210 | AG43: 0.083333333 | AH43: Turquía | AI43: Bélgica
AE44: 95 | AF44: 46210 | AG44: 0.75 | AH44: Argentina | AI44: EEUU
B45: Grupo J | E45: Resultado | G45: 1X2 | H45: Ptos | I45: Ptos | L45: Grupo K | O45: Resultado | Q45: 1X2 | R45: Ptos | S45: Ptos | V45: Grupo L | Y45: Resultado | AA45: 1X2 | AB45: Ptos | AC45: Ptos | AE45: 96 | AF45: 46210 | AG45: 0.91666667 | AH45: Suiza | AI45: Portugal
B46: 46190 | C46: 0.125 | D46: Argentina | E46: 2-0 | F46: Argelia | G46: 1 | L46: 46190 | M46: 0.79166667 | N46: Portugal | O46: 3-0 | P46: Congo | Q46: 1 | V46: 46190 | W46: 0.91666667 | X46: Inglaterra | Y46: 2-1 | Z46: Croacia | AA46: 1
B47: 46190 | C47: 0.25 | D47: Austria | E47: 1-0 | F47: Jordania | G47: 1 | L47: 46191 | M47: 0.16666667 | N47: Uzbekistan | O47: 0-2 | P47: Colombia | Q47: 2 | V47: 46191 | W47: 0.041666667 | X47: Ghana | Y47: 2-1 | Z47: Panama | AA47: 1 | AF47: CUARTOS
B48: 46195 | C48: 0.79166667 | D48: Argentina | E48: 2-0 | F48: Austria | G48: 1 | L48: 46196 | M48: 0.79166667 | N48: Portugal | O48: 3-0 | P48: Uzbekistan | Q48: 1 | V48: 46196 | W48: 0.91666667 | X48: Inglaterra | Y48: 1-0 | Z48: Ghana | AA48: 1 | AF48: 50ptos/equipo ó 75ptos/equipo+casilla | AJ48: Ptos
B49: 46196 | C49: 0.20833333 | D49: Jordania | E49: 1-2 | F49: Argelia | G49: 2 | L49: 46197 | M49: 0.16666667 | N49: Colombia | O49: 2-0 | P49: Congo | Q49: 1 | V49: 46197 | W49: 0.041666667 | X49: Panama | Y49: 0-3 | Z49: Croacia | AA49: 2 | AE49: 97 | AF49: 46212 | AG49: 0.91666667 | AH49: Francia | AI49: Países Bajos
B50: 46201 | C50: 0.16666667 | D50: Argelia | E50: 2-3 | F50: Austria | G50: 2 | L50: 46201 | M50: 0.0625 | N50: Colombia | O50: 2-2 | P50: Portugal | Q50: X | V50: 46200 | W50: 0.95833333 | X50: Panama | Y50: 0-5 | Z50: Inglaterra | AA50: 2 | AE50: 98 | AF50: 46213 | AG50: 0.875 | AH50: España | AI50: Turquía
B51: 46201 | C51: 0.16666667 | D51: Jordania | E51: 0-3 | F51: Argentina | G51: 2 | L51: 46201 | M51: 0.0625 | N51: Congo | O51: 0-1 | P51: Uzbekistan | Q51: 2 | V51: 46200 | W51: 0.95833333 | X51: Croacia | Y51: 2-2 | Z51: Ghana | AA51: X | AE51: 99 | AF51: 46214 | AG51: 0.95833333 | AH51: Brasil | AI51: Inglaterra
...

Sheet RAMON 2
B2: Selección Española | C2: 15puntos | D2: Ptos
B3: Caerá España en penaltis | C3: NO
B4: Se lesionará alguien (lesión, no molestias…) | C4: SI
B5: Anularan a España algun gol por el VAR | C5: SI
B6: Se perderá alguien algún partido por sanción | C6: SI
B7: Marcara Victor Muñoz (no vale penalti) | C7: NO
B8: Luis de la Fuente verá tarjeta? | C8: NO
B9: Jugara algún minuto Yeremy Pino | C9: SI
B10: Jugará otro portero que no sea Unai Simon | C10: SI
C11: 30puntos
B12: Primer tarjeteado | C12: Cucurella
B13: Quien marcará más goles (Victor Muñoz, Borja Iglesias, Yeremy Pino) | C13: Borja Iglesias
B14: Quien marcará más goles (Oyarzabal, Dani Olmo, Yamal) | C14: Oyarzabal
B15: Quien dará más asistencias (Pedri, Yamal, Zubimendi) | C15: Yamal
B16: Quien recibirá más tarjetas amarillas (Cucurella, Pedro Porro, Le Normand) | C16: Pedro Porro
B17: Primer cambio (primero en salir del campo) | C17: Zubimendi
B18: Primer cambio (primero en entrar al campo) | C18: Alex Baena
B19: Cuántos partidos jugará España | C19: 7
C20: 60puntos
B21: Máximo goleador | C21: Oyarzabal
B22: Maximo asistente | C22: Yamal
B23: Cuántos goles marcará España | C23: 12
B24: Cuántos goles le marcarán a España | C24: 4
D25: =SUM(D3:D24) -> 0
B27: Generales | C27: 15puntos | D27: Ptos
B28: Marcara Cristiano de falta | C28: NO
B29: Cuántos 0-0 habrá en la fase de grupos | C29: 2
B30: Primera selección en marcar un gol (no cuenta en propia) | C30: Mexico | F30: ALINEACION | G30: =[4]RAMON!H72 -> 0
B31: Primera selección en recibir una tarjeta | C31: Sudafrica | F31: PRONÓSTICOS: | G31: =[4]RAMON!AB53+[4]RAMON!AC53 -> 0
B32: Mayor número de goles que habrá en un partido. Solo 90 min | C32: 6 | F32: GOLES: | G32: =SUM([4]RAMON!R60:R64)*40 -> 0
B33: Mayor goleada (diferencia de goles entre los 2 equipos). Solo 90 min | C33: 5 | F33: PORTEROS | G33: =SUM([4]RAMON!AA61:AA63)*30+SUM([4]RAMON!AB61:AB63)*40 -> 0
C34: 30puntos | F34: PREGUNTAS: | G34: =G59 -> 0
B35: Número de goles del máximo goleador | C35: 7 | F35: PUNTUACIÓN FINAL | G35: =SUM(G28:G34) -> 0
B36: Selección más goleadora | C36: España
B37: Selección menos goleada | C37: Inglaterra
B38: Selección más goleada | C38: Haití
B39: Selección menos goleadora | C39: Haití
B40: Primera selección en parar un penalti | C40: Argentina
B41: Primera selección con un jugador expulsado | C41: Uruguay
B42: Acabará alguna selección con 0 puntos | C42: SI
...

Sheet DAVID
AF2: Participación: 20 €
K4: MACROPORRA MUNDIAL 2026
K8: Nombre: | M8: DAVID
K11: e-mail: | M11: DADEGAR@GMAIL.COM
B14: Guarda el archivo con tu nombre y envíalo a iperezurrutia@gmail.com o por WHATSAPP Fecha límite de envío y de pago: Primer partido Mundial (11/06/2026 21:00)
B16: ESCRIBE UN SIGNO (10 PUNTOS) Y UN RESULTADO (25 PUNTOS)
AF17: DIECISEISAVOS
B18: Grupo A | E18: Resultado | G18: 1X2 | H18: Ptos | I18: Ptos | L18: Grupo B | O18: Resultado | Q18: 1X2 | R18: Ptos | S18: Ptos | V18: Grupo C | Y18: Resultado | AA18: 1X2 | AB18: Ptos | AC18: Ptos | AF18: 20ptos/equipo ó 40ptos/equipo+casilla | AJ18: Ptos
B19: 46184 | C19: 0.875 | D19: Mexico | E19: 1-1 | F19: Sudafrica | G19: X | L19: 46185 | M19: 0.875 | N19: Canada | O19: 0-2 | P19: Bosnia | Q19: 2 | V19: 46187 | W19: 0 | X19: Brasil | Y19: 1-1 | Z19: Marruecos | AA19: X | AE19: 73 | AF19: 46201 | AG19: 0.875 | AH19: COREA DEL SUR | AI19: SUIZA
B20: 46185 | C20: 0.16666667 | D20: Corea del Sur | E20: 1-0 | F20: Chequia | G20: 1 | L20: 46186 | M20: 0.875 | N20: Catar | O20: 0-1 | P20: Suiza | Q20: 2 | V20: 46187 | W20: 0.125 | X20: Haiti | Y20: 0-2 | Z20: Escocia | AA20: 2 | AE20: 74 | AF20: 46202 | AG20: 0.9375 | AH20: ALEMANIA | AI20: ESCOCIA
B21: 46191 | C21: 0.75 | D21: Chequia | E21: 2-0 | F21: Sudafrica | G21: 1 | L21: 46191 | M21: 0.875 | N21: Suiza | O21: 2-2 | P21: Bosnia | Q21: X | V21: 46193 | W21: 0 | X21: Escocia | Y21: 0-2 | Z21: Marruecos | AA21: 2 | AE21: 75 | AF21: 46203 | AG21: 0.125 | AH21: PAÍSES BAJOS | AI21: MARRUECOS
B22: 46192 | C22: 0.125 | D22: Mexico | E22: 2-1 | F22: Corea del Sur | G22: 1 | L22: 46192 | M22: 0 | N22: Canada | O22: 2-0 | P22: Catar | Q22: 1 | V22: 46193 | W22: 0.10416667 | X22: Brasil | Y22: 4-0 | Z22: Haiti | AA22: 1 | AE22: 76 | AF22: 46202 | AG22: 0.79166667 | AH22: BRASIL | AI22: SUECIA
B23: 46198 | C23: 0.125 | D23: Chequia | E23: 1-2 | F23: Mexico | G23: 2 | L23: 46197 | M23: 0.875 | N23: Bosnia | O23: 2-0 | P23: Catar | Q23: 1 | V23: 46198 | W23: 0 | X23: Escocia | Y23: 1-2 | Z23: Brasil | AA23: 2 | AE23: 77 | AF23: 46203 | AG23: 0.95833333 | AH23: FRANCIA | AI23: PARAGUAY
B24: 46198 | C24: 0.125 | D24: Sudafrica | E24: 0-2 | F24: Corea del Sur | G24: 2 | L24: 46197 | M24: 0.875 | N24: Suiza | O24: 1-0 | P24: Canada | Q24: 1 | V24: 46198 | W24: 0 | X24: Marruecos | Y24: 3-0 | Z24: Haiti | AA24: 1 | AE24: 78 | AF24: 46203 | AG24: 0.79166667 | AH24: COSTA DE MARFIL | AI24: SENEGAL
